{"uuid": "4372ffee-1b47-4d54-9e9d-5c0b340fc334", "children": ["fccb05bb-6b7d-4a81-9503-09d54bef3d9a", "cad60b7e-52bc-4dbb-9d8b-b66a359fc2b6"], "befores": [{"name": "_Class__pytest_setup_class", "status": "broken", "statusDetails": {"message": "urllib3.exceptions.MaxRetryError: HTTPConnectionPool(host='127.0.0.1', port=4723): Max retries exceeded with url: /wd/hub/session (Caused by NewConnectionError('<urllib3.connection.HTTPConnection object at 0x110b83d50>: Failed to establish a new connection: [Errno 61] Connection refused'))\n", "trace": "  File \"/Library/Frameworks/Python.framework/Versions/3.7/lib/python3.7/site-packages/pluggy/callers.py\", line 187, in _multicall\n    res = hook_impl.function(*args)\n  File \"/Library/Frameworks/Python.framework/Versions/3.7/lib/python3.7/site-packages/_pytest/fixtures.py\", line 923, in pytest_fixture_setup\n    result = call_fixture_func(fixturefunc, request, kwargs)\n  File \"/Library/Frameworks/Python.framework/Versions/3.7/lib/python3.7/site-packages/_pytest/fixtures.py\", line 779, in call_fixture_func\n    res = next(it)\n  File \"/Library/Frameworks/Python.framework/Versions/3.7/lib/python3.7/site-packages/_pytest/python.py\", line 747, in xunit_setup_class_fixture\n    _call_with_optional_argument(func, self.obj)\n  File \"/Library/Frameworks/Python.framework/Versions/3.7/lib/python3.7/site-packages/_pytest/python.py\", line 686, in _call_with_optional_argument\n    func(arg)\n  File \"/Users/xuanlonghua/Documents/ZD/Projects/appium_autotest/scripts/test_admin_create.py\", line 17, in setup_class\n    self.driver = init_driver()\n  File \"/Users/xuanlonghua/Documents/ZD/Projects/appium_autotest/common/init_driver.py\", line 25, in init_driver\n    driver = webdriver.Remote(command_executor,desired_caps)\n  File \"/Library/Frameworks/Python.framework/Versions/3.7/lib/python3.7/site-packages/appium/webdriver/webdriver.py\", line 144, in __init__\n    proxy\n  File \"/Library/Frameworks/Python.framework/Versions/3.7/lib/python3.7/site-packages/selenium/webdriver/remote/webdriver.py\", line 157, in __init__\n    self.start_session(capabilities, browser_profile)\n  File \"/Library/Frameworks/Python.framework/Versions/3.7/lib/python3.7/site-packages/appium/webdriver/webdriver.py\", line 219, in start_session\n    response = self.execute(RemoteCommand.NEW_SESSION, parameters)\n  File \"/Library/Frameworks/Python.framework/Versions/3.7/lib/python3.7/site-packages/selenium/webdriver/remote/webdriver.py\", line 319, in execute\n    response = self.command_executor.execute(driver_command, params)\n  File \"/Library/Frameworks/Python.framework/Versions/3.7/lib/python3.7/site-packages/selenium/webdriver/remote/remote_connection.py\", line 374, in execute\n    return self._request(command_info[0], url, body=data)\n  File \"/Library/Frameworks/Python.framework/Versions/3.7/lib/python3.7/site-packages/selenium/webdriver/remote/remote_connection.py\", line 397, in _request\n    resp = self._conn.request(method, url, body=body, headers=headers)\n  File \"/Library/Frameworks/Python.framework/Versions/3.7/lib/python3.7/site-packages/urllib3/request.py\", line 72, in request\n    **urlopen_kw)\n  File \"/Library/Frameworks/Python.framework/Versions/3.7/lib/python3.7/site-packages/urllib3/request.py\", line 150, in request_encode_body\n    return self.urlopen(method, url, **extra_kw)\n  File \"/Library/Frameworks/Python.framework/Versions/3.7/lib/python3.7/site-packages/urllib3/poolmanager.py\", line 326, in urlopen\n    response = conn.urlopen(method, u.request_uri, **kw)\n  File \"/Library/Frameworks/Python.framework/Versions/3.7/lib/python3.7/site-packages/urllib3/connectionpool.py\", line 670, in urlopen\n    **response_kw)\n  File \"/Library/Frameworks/Python.framework/Versions/3.7/lib/python3.7/site-packages/urllib3/connectionpool.py\", line 670, in urlopen\n    **response_kw)\n  File \"/Library/Frameworks/Python.framework/Versions/3.7/lib/python3.7/site-packages/urllib3/connectionpool.py\", line 670, in urlopen\n    **response_kw)\n  File \"/Library/Frameworks/Python.framework/Versions/3.7/lib/python3.7/site-packages/urllib3/connectionpool.py\", line 641, in urlopen\n    _stacktrace=sys.exc_info()[2])\n  File \"/Library/Frameworks/Python.framework/Versions/3.7/lib/python3.7/site-packages/urllib3/util/retry.py\", line 399, in increment\n    raise MaxRetryError(_pool, url, error or ResponseError(cause))\n"}, "start": 1591975200204, "stop": 1591975200210}], "start": 1591975200204, "stop": 1591975200531}