{"uuid": "bef621a2-4646-434d-927c-66a2e4aded19", "children": ["e7eac2fe-c626-4a18-847f-2ae90d5f9d82", "a7d90c56-f835-4942-aa50-74d57f3075be"], "befores": [{"name": "_Class__pytest_setup_class", "status": "broken", "statusDetails": {"message": "selenium.common.exceptions.WebDriverException: Message: An unknown server-side error occurred while processing the command. Original error: Unable to find an active device or emulator with OS 8.0. The following are available: fe80849 (8.1.0)\n\n", "trace": "  File \"/Library/Frameworks/Python.framework/Versions/3.7/lib/python3.7/site-packages/pluggy/callers.py\", line 187, in _multicall\n    res = hook_impl.function(*args)\n  File \"/Library/Frameworks/Python.framework/Versions/3.7/lib/python3.7/site-packages/_pytest/fixtures.py\", line 923, in pytest_fixture_setup\n    result = call_fixture_func(fixturefunc, request, kwargs)\n  File \"/Library/Frameworks/Python.framework/Versions/3.7/lib/python3.7/site-packages/_pytest/fixtures.py\", line 779, in call_fixture_func\n    res = next(it)\n  File \"/Library/Frameworks/Python.framework/Versions/3.7/lib/python3.7/site-packages/_pytest/python.py\", line 747, in xunit_setup_class_fixture\n    _call_with_optional_argument(func, self.obj)\n  File \"/Library/Frameworks/Python.framework/Versions/3.7/lib/python3.7/site-packages/_pytest/python.py\", line 686, in _call_with_optional_argument\n    func(arg)\n  File \"/Users/xuanlonghua/Documents/ZD/Projects/appium_autotest/scripts/test_admin_create.py\", line 17, in setup_class\n    self.driver = init_driver()\n  File \"/Users/xuanlonghua/Documents/ZD/Projects/appium_autotest/common/init_driver.py\", line 25, in init_driver\n    driver = webdriver.Remote(command_executor,desired_caps)\n  File \"/Library/Frameworks/Python.framework/Versions/3.7/lib/python3.7/site-packages/appium/webdriver/webdriver.py\", line 144, in __init__\n    proxy\n  File \"/Library/Frameworks/Python.framework/Versions/3.7/lib/python3.7/site-packages/selenium/webdriver/remote/webdriver.py\", line 157, in __init__\n    self.start_session(capabilities, browser_profile)\n  File \"/Library/Frameworks/Python.framework/Versions/3.7/lib/python3.7/site-packages/appium/webdriver/webdriver.py\", line 219, in start_session\n    response = self.execute(RemoteCommand.NEW_SESSION, parameters)\n  File \"/Library/Frameworks/Python.framework/Versions/3.7/lib/python3.7/site-packages/selenium/webdriver/remote/webdriver.py\", line 321, in execute\n    self.error_handler.check_response(response)\n  File \"/Library/Frameworks/Python.framework/Versions/3.7/lib/python3.7/site-packages/selenium/webdriver/remote/errorhandler.py\", line 242, in check_response\n    raise exception_class(message, screen, stacktrace)\n"}, "start": 1591975366590, "stop": 1591975366654}], "start": 1591975366590, "stop": 1591975366766}